{"uuid": "209227eb-87c8-4146-99b2-ab38ff2bf8a1", "children": ["adc7d543-c7b1-4326-a10f-029e455218bd"], "befores": [{"name": "_xunit_setup_method_fixture_TestCarcenter", "status": "broken", "statusDetails": {"message": "selenium.common.exceptions.WebDriverException: Message: An unknown server-side error occurred while processing the command. Original error: Could not find a connected Android device in 20000ms\nStacktrace:\nUnknownError: An unknown server-side error occurred while processing the command. Original error: Could not find a connected Android device in 20000ms\n    at getResponseForW3CError (D:\\software\\nodejs\\node_global\\node_modules\\appium\\node_modules\\@appium\\base-driver\\lib\\protocol\\errors.js:1092:9)\n    at asyncHandler (D:\\software\\nodejs\\node_global\\node_modules\\appium\\node_modules\\@appium\\base-driver\\lib\\protocol\\protocol.js:491:57)\n", "trace": "  File \"D:\\software\\Python310\\lib\\site-packages\\pluggy\\_callers.py\", line 77, in _multicall\n    res = hook_impl.function(*args)\n  File \"D:\\software\\Python310\\lib\\site-packages\\_pytest\\fixtures.py\", line 1123, in pytest_fixture_setup\n    result = call_fixture_func(fixturefunc, request, kwargs)\n  File \"D:\\software\\Python310\\lib\\site-packages\\_pytest\\fixtures.py\", line 895, in call_fixture_func\n    fixture_result = next(generator)\n  File \"D:\\software\\Python310\\lib\\site-packages\\_pytest\\python.py\", line 899, in xunit_setup_method_fixture\n    _call_with_optional_argument(func, method)\n  File \"D:\\software\\Python310\\lib\\site-packages\\_pytest\\python.py\", line 779, in _call_with_optional_argument\n    func()\n  File \"E:\\DM\\ShirleyPytest\\scripts\\test03_click_appicon.py\", line 19, in setup_method\n    self.driver = init_driver()\n  File \"E:\\DM\\ShirleyPytest\\base\\base_driver.py\", line 16, in init_driver\n    driver = webdriver.Remote(\"http://127.0.0.1:4723\", caps)\n  File \"D:\\software\\Python310\\lib\\site-packages\\appium\\webdriver\\webdriver.py\", line 257, in __init__\n    super().__init__(\n  File \"D:\\software\\Python310\\lib\\site-packages\\selenium\\webdriver\\remote\\webdriver.py\", line 205, in __init__\n    self.start_session(capabilities)\n  File \"D:\\software\\Python310\\lib\\site-packages\\appium\\webdriver\\webdriver.py\", line 346, in start_session\n    response = self.execute(RemoteCommand.NEW_SESSION, w3c_caps)\n  File \"D:\\software\\Python310\\lib\\site-packages\\selenium\\webdriver\\remote\\webdriver.py\", line 344, in execute\n    self.error_handler.check_response(response)\n  File \"D:\\software\\Python310\\lib\\site-packages\\selenium\\webdriver\\remote\\errorhandler.py\", line 229, in check_response\n    raise exception_class(message, screen, stacktrace)\n"}, "start": 1699842882213, "stop": 1699842902382}], "start": 1699842882213, "stop": 1699842902477}